Workbook

Sheet Maio_21
B2: Escala de Trabalho | E2: Férias | F2: Trabalhando | G2: Folga
B5: Dias | C5: Sábado | D5: Domingo | E5: Segunda-feira | F5: Terça-feira | G5: Quarta-feira | H5: Quinta-feira | I5: Sexta-feira
B6: PDV | C6: 44324 | D6: 44325 | E6: 44326 | F6: 44327 | G6: 44328 | H6: 44329 | I6: 44330
B7: Penha | C7: Andressa | D7: Andressa | E7: Andressa | F7: Andressa | G7: Andressa | H7: Andressa | I7: Andressa
B8: Penha | C8: Isadora | D8: Isadora | E8: Isadora | F8: Isadora | G8: Isadora | H8: Isadora | I8: Isadora
B9: Penha | C9: Christian | D9: Christian | E9: Christian | F9: Christian | G9: Christian | H9: Christian | I9: Christian
B10: Piçarras | C10: Miguel | D10: Miguel | E10: Miguel | F10: Miguel | G10: Miguel | H10: Miguel | I10: Miguel
B11: Piçarras | C11: Priscila | D11: Priscila | E11: Priscila | F11: Priscila | G11: Priscila | H11: Priscila | I11: Priscila
B12: Piçarras | C12: Milena | D12: Milena | E12: Milena | F12: Milena | G12: Milena | H12: Milena | I12: Milena
B13: Piçarras/Penha | C13: Luiz | D13: Luiz | E13: Luiz | F13: Luiz | G13: Luiz | H13: Luiz | I13: Luiz
B14: Piçarras/Penha | C14: Jean | D14: Jean | E14: Jean | F14: Jean | G14: Jean | H14: Jean | I14: Jean
B15: Externo | C15: Diogo | D15: Diogo | E15: Diogo | F15: Diogo | G15: Diogo | H15: Diogo | I15: Diogo
B17: Dias | C17: Sábado | D17: Domingo | E17: Segunda-feira | F17: Terça-feira | G17: Quarta-feira | H17: Quinta-feira | I17: Sexta-feira
B18: PDV | C18: 44331 | D18: 44332 | E18: 44333 | F18: 44334 | G18: 44335 | H18: 44336 | I18: 44337
B19: Penha | C19: Andressa | D19: Andressa | E19: Andressa | F19: Andressa | G19: Andressa | H19: Andressa | I19: Andressa
B20: Penha | C20: Isadora | D20: Isadora | E20: Isadora | F20: Isadora | G20: Isadora | H20: Isadora | I20: Isadora
B21: Penha | C21: Christian | D21: Christian | E21: Christian | F21: Christian | G21: Christian | H21: Christian | I21: Christian
B22: Piçarras | C22: Miguel | D22: Miguel | E22: Miguel | F22: Miguel | G22: Miguel | H22: Miguel | I22: Miguel
B23: Piçarras | C23: Priscila | D23: Priscila | E23: Priscila | F23: Priscila | G23: Priscila | H23: Priscila | I23: Priscila
B24: Piçarras | C24: Milena | D24: Milena | E24: Milena | F24: Milena | G24: Milena | H24: Milena | I24: Milena
B25: Piçarras/Penha | C25: Luiz | D25: Luiz | E25: Luiz | F25: Luiz | G25: Luiz | H25: Luiz | I25: Luiz
B26: Piçarras/Penha | C26: Jean | D26: Jean | E26: Jean | F26: Jean | G26: Jean | H26: Jean | I26: Jean
B27: Externo | C27: Diogo | D27: Diogo | E27: Diogo | F27: Diogo | G27: Diogo | H27: Diogo | I27: Diogo
B29: Dias | C29: Sábado | D29: Domingo | E29: Segunda-feira | F29: Terça-feira | G29: Quarta-feira | H29: Quinta-feira | I29: Sexta-feira
B30: PDV | C30: 44338 | D30: 44339 | E30: 44340 | F30: 44341 | G30: 44342 | H30: 44343 | I30: 44344
B31: Penha | C31: Andressa | D31: Andressa | E31: Andressa | F31: Andressa | G31: Andressa | H31: Andressa | I31: Andressa
B32: Penha | C32: Isadora | D32: Isadora | E32: Isadora | F32: Isadora | G32: Isadora | H32: Isadora | I32: Isadora
B33: Penha | C33: Christian | D33: Christian | E33: Christian | F33: Christian | G33: Christian | H33: Christian | I33: Christian
B34: Piçarras | C34: Miguel | D34: Miguel | E34: Miguel | F34: Miguel | G34: Miguel | H34: Miguel | I34: Miguel
B35: Piçarras | C35: Priscila | D35: Priscila | E35: Priscila | F35: Priscila | G35: Priscila | H35: Priscila | I35: Priscila
B36: Piçarras | C36: Milena | D36: Milena | E36: Milena | F36: Milena | G36: Milena | H36: Milena | I36: Milena
B37: Piçarras/Penha | C37: Luiz | D37: Luiz | E37: Luiz | F37: Luiz | G37: Luiz | H37: Luiz | I37: Luiz
B38: Piçarras/Penha | C38: Jean | D38: Jean | E38: Jean | F38: Jean | G38: Jean | H38: Jean | I38: Jean
B39: Externo | C39: Diogo | D39: Diogo | E39: Diogo | F39: Diogo | G39: Diogo | H39: Diogo | I39: Diogo
B41: Dias | C41: Sábado | D41: Domingo | E41: Segunda-feira | F41: Terça-feira | G41: Quarta-feira | H41: Quinta-feira | I41: Sexta-feira
B42: PDV | C42: 44345 | D42: 44346 | E42: 44347 | F42: 44348 | G42: 44349 | H42: 44350 | I42: 44351
B43: Penha | C43: Andressa | D43: Andressa | E43: Andressa | F43: Andressa | G43: Andressa | H43: Andressa | I43: Andressa
B44: Penha | C44: Isadora | D44: Isadora | E44: Isadora | F44: Isadora | G44: Isadora | H44: Isadora | I44: Isadora
B45: Penha | C45: Christian | D45: Christian | E45: Christian | F45: Christian | G45: Christian | H45: Christian | I45: Christian
B46: Piçarras | C46: Miguel | D46: Miguel | E46: Miguel | F46: Miguel | G46: Miguel | H46: Miguel | I46: Miguel
...

Sheet Junho_21
B2: Escala de Trabalho | E2: Férias | F2: Trabalhando | G2: Folga
B4: Dias | C4: Sábado | D4: Domingo | E4: Segunda-feira | F4: Terça-feira | G4: Quarta-feira | H4: Quinta-feira | I4: Sexta-feira
B5: PDV | C5: 44352 | D5: 44353 | E5: 44354 | F5: 44355 | G5: 44356 | H5: 44357 | I5: 44358
B6: Penha | C6: Andressa | D6: Andressa | E6: Andressa | F6: Andressa | G6: Andressa | H6: Andressa | I6: Andressa
B7: Penha | C7: Isadora | D7: Isadora | E7: Isadora | F7: Isadora | G7: Isadora | H7: Isadora | I7: Isadora
B8: Penha | C8: Christian | D8: Christian | E8: Christian | F8: Christian | G8: Christian | H8: Christian | I8: Christian
B9: Piçarras | C9: Miguel | D9: Miguel | E9: Miguel | F9: Miguel | G9: Miguel | H9: Miguel | I9: Miguel
B10: Piçarras | C10: Priscila | D10: Priscila | E10: Priscila | F10: Priscila | G10: Priscila | H10: Priscila | I10: Priscila
B11: Piçarras/Penha | C11: Luiz | D11: Luiz | E11: Luiz | F11: Luiz | G11: Luiz | H11: Luiz | I11: Luiz
B12: Piçarras/Penha | C12: Jean | D12: Jean | E12: Jean | F12: Jean | G12: Jean | H12: Jean | I12: Jean
B13: Externo | C13: Diogo | D13: Diogo | E13: Diogo | F13: Diogo | G13: Diogo | H13: Diogo | I13: Diogo
B15: Dias | C15: Sábado | D15: Domingo | E15: Segunda-feira | F15: Terça-feira | G15: Quarta-feira | H15: Quinta-feira | I15: Sexta-feira
B16: PDV | C16: 44359 | D16: 44360 | E16: 44361 | F16: 44362 | G16: 44363 | H16: 44364 | I16: 44365
B17: Penha | C17: Andressa | D17: Andressa | E17: Andressa | F17: Andressa | G17: Andressa | H17: Andressa | I17: Andressa
B18: Penha | C18: Isadora | D18: Isadora | E18: Isadora | F18: Isadora | G18: Isadora | H18: Isadora | I18: Isadora
B19: Penha | C19: Christian | D19: Christian | E19: Christian | F19: Christian | G19: Christian | H19: Christian | I19: Christian
B20: Piçarras | C20: Miguel | D20: Miguel | E20: Miguel | F20: Miguel | G20: Miguel | H20: Miguel | I20: Miguel
B21: Piçarras | C21: Priscila | D21: Priscila | E21: Priscila | F21: Priscila | G21: Priscila | H21: Priscila | I21: Priscila
B22: Piçarras/Penha | C22: Luiz | D22: Luiz | E22: Luiz | F22: Luiz | G22: Luiz | H22: Luiz | I22: Luiz
B23: Piçarras/Penha | C23: Jean | D23: Jean | E23: Jean | F23: Jean | G23: Jean | H23: Jean | I23: Jean
B24: Externo | C24: Diogo | D24: Diogo | E24: Diogo | F24: Diogo | G24: Diogo | H24: Diogo | I24: Diogo
B26: Dias | C26: Sábado | D26: Domingo | E26: Segunda-feira | F26: Terça-feira | G26: Quarta-feira | H26: Quinta-feira | I26: Sexta-feira
B27: PDV | C27: 44366 | D27: 44367 | E27: 44368 | F27: 44369 | G27: 44370 | H27: 44371 | I27: 44372
B28: Penha | C28: Andressa | D28: Andressa | E28: Andressa | F28: Andressa | G28: Andressa | H28: Andressa | I28: Andressa
B29: Penha | C29: Isadora | D29: Isadora | E29: Isadora | F29: Isadora | G29: Isadora | H29: Isadora | I29: Isadora
B30: Penha | C30: Christian | D30: Christian | E30: Christian | F30: Christian | G30: Christian | H30: Christian | I30: Christian
B31: Piçarras | C31: Miguel | D31: Miguel | E31: Miguel | F31: Miguel | G31: Miguel | H31: Miguel | I31: Miguel
B32: Piçarras | C32: Priscila | D32: Priscila | E32: Priscila | F32: Priscila | G32: Priscila | H32: Priscila | I32: Priscila
B33: Piçarras/Penha | C33: Luiz | D33: Luiz | E33: Luiz | F33: Luiz | G33: Luiz | H33: Luiz | I33: Luiz
B34: Piçarras/Penha | C34: Jean | D34: Jean | E34: Jean | F34: Jean | G34: Jean | H34: Jean | I34: Jean
B35: Externo | C35: Diogo | D35: Diogo | E35: Diogo | F35: Diogo | G35: Diogo | H35: Diogo | I35: Diogo
B37: Dias | C37: Sábado | D37: Domingo | E37: Segunda-feira | F37: Terça-feira | G37: Quarta-feira | H37: Quinta-feira | I37: Sexta-feira
B38: PDV | C38: 44373 | D38: 44374 | E38: 44375 | F38: 44376 | G38: 44377 | H38: 44378 | I38: 44379
B39: Penha | C39: Andressa | D39: Andressa | E39: Andressa | F39: Andressa | G39: Andressa | H39: Andressa | I39: Andressa
B40: Penha | C40: Isadora | D40: Isadora | E40: Isadora | F40: Isadora | G40: Isadora | H40: Isadora | I40: Isadora
B41: Penha | C41: Christian | D41: Christian | E41: Christian | F41: Christian | G41: Christian | H41: Christian | I41: Christian
B42: Piçarras | C42: Miguel | D42: Miguel | E42: Miguel | F42: Miguel | G42: Miguel | H42: Miguel | I42: Miguel
B43: Piçarras | C43: Priscila | D43: Priscila | E43: Priscila | F43: Priscila | G43: Priscila | H43: Priscila | I43: Priscila
B44: Piçarras/Penha | C44: Luiz | D44: Luiz | E44: Luiz | F44: Luiz | G44: Luiz | H44: Luiz | I44: Luiz
B45: Piçarras/Penha | C45: Jean | D45: Jean | E45: Jean | F45: Jean | G45: Jean | H45: Jean | I45: Jean
...

Sheet Julho_21
B2: Dias | C2: Sábado | D2: Domingo | E2: Segunda-feira | F2: Terça-feira | G2: Quarta-feira | H2: Quinta-feira | I2: Sexta-feira
B3: PDV | C3: 44380 | D3: 44381 | E3: 44382 | F3: 44383 | G3: 44384 | H3: 44385 | I3: 44386
B4: Penha | C4: Andressa | D4: Andressa | E4: Andressa | F4: Andressa | G4: Andressa | H4: Andressa | I4: Andressa
B5: Penha | C5: Isadora | D5: Isadora | E5: Isadora | F5: Isadora | G5: Isadora | H5: Isadora | I5: Isadora
B6: Penha | C6: Christian | D6: Christian | E6: Christian | F6: Christian | G6: Christian | H6: Christian | I6: Christian
B7: Piçarras | C7: Miguel | D7: Miguel | E7: Miguel | F7: Miguel | G7: Miguel | H7: Miguel | I7: Miguel
B8: Piçarras | C8: Priscila | D8: Priscila | E8: Priscila | F8: Priscila | G8: Priscila | H8: Priscila | I8: Priscila
B9: Piçarras/Penha | C9: Luiz | D9: Luiz | E9: Luiz | F9: Luiz | G9: Luiz | H9: Luiz | I9: Luiz
B10: Piçarras/Penha | C10: Jean | D10: Jean | E10: Jean | F10: Jean | G10: Jean | H10: Jean | I10: Jean
B11: Externo | C11: Diogo | D11: Diogo | E11: Diogo | F11: Diogo | G11: Diogo | H11: Diogo | I11: Diogo
B13: Dias | C13: Sábado | D13: Domingo | E13: Segunda-feira | F13: Terça-feira | G13: Quarta-feira | H13: Quinta-feira | I13: Sexta-feira
B14: PDV | C14: 44387 | D14: 44388 | E14: 44389 | F14: 44390 | G14: 44391 | H14: 44392 | I14: 44393
B15: Penha | C15: Andressa | D15: Andressa | E15: Andressa | F15: Andressa | G15: Andressa | H15: Andressa | I15: Andressa
B16: Penha | C16: Isadora | D16: Isadora | E16: Isadora | F16: Isadora | G16: Isadora | H16: Isadora | I16: Isadora
B17: Penha | C17: Christian | D17: Christian | E17: Christian | F17: Christian | G17: Christian | H17: Christian | I17: Christian
B18: Piçarras | C18: Miguel | D18: Miguel | E18: Miguel | F18: Miguel | G18: Miguel | H18: Miguel | I18: Miguel
B19: Piçarras | C19: Priscila | D19: Priscila | E19: Priscila | F19: Priscila | G19: Priscila | H19: Priscila | I19: Priscila
B20: Piçarras/Penha | C20: Luiz | D20: Luiz | E20: Luiz | F20: Luiz | G20: Luiz | H20: Luiz | I20: Luiz
B21: Piçarras/Penha | C21: Jean | D21: Jean | E21: Jean | F21: Jean | G21: Jean | H21: Jean | I21: Jean
B22: Externo | C22: Diogo | D22: Diogo | E22: Diogo | F22: Diogo | G22: Diogo | H22: Diogo | I22: Diogo
B24: Dias | C24: Sábado | D24: Domingo | E24: Segunda-feira | F24: Terça-feira | G24: Quarta-feira | H24: Quinta-feira | I24: Sexta-feira
B25: PDV | C25: 44394 | D25: 44395 | E25: 44396 | F25: 44397 | G25: 44398 | H25: 44399 | I25: 44400
B26: Penha | C26: Andressa | D26: Andressa | E26: Andressa | F26: Andressa | G26: Andressa | H26: Andressa | I26: Andressa
B27: Penha | C27: Isadora | D27: Isadora | E27: Isadora | F27: Isadora | G27: Isadora | H27: Isadora | I27: Isadora
B28: Penha | C28: Christian | D28: Christian | E28: Christian | F28: Christian | G28: Christian | H28: Christian | I28: Christian
B29: Piçarras | C29: Miguel | D29: Miguel | E29: Miguel | F29: Miguel | G29: Miguel | H29: Miguel | I29: Miguel
B30: Piçarras | C30: Priscila | D30: Priscila | E30: Priscila | F30: Priscila | G30: Priscila | H30: Priscila | I30: Priscila
B31: Piçarras/Penha | C31: Luiz | D31: Luiz | E31: Luiz | F31: Luiz | G31: Luiz | H31: Luiz | I31: Luiz
B32: Piçarras/Penha | C32: Jean | D32: Jean | E32: Jean | F32: Jean | G32: Jean | H32: Jean | I32: Jean
B33: Externo | C33: Diogo | D33: Diogo | E33: Diogo | F33: Diogo | G33: Diogo | H33: Diogo | I33: Diogo
B35: Dias | C35: Sábado | D35: Domingo | E35: Segunda-feira | F35: Terça-feira | G35: Quarta-feira | H35: Quinta-feira | I35: Sexta-feira
B36: PDV | C36: 44401 | D36: 44402 | E36: 44403 | F36: 44404 | G36: 44405 | H36: 44406 | I36: 44407
B37: Penha | C37: Andressa | D37: Andressa | E37: Andressa | F37: Andressa | G37: Andressa | H37: Andressa | I37: Andressa
B38: Penha | C38: Isadora | D38: Isadora | E38: Isadora | F38: Isadora | G38: Isadora | H38: Isadora | I38: Isadora
B39: Penha | C39: Christian | D39: Christian | E39: Christian | F39: Christian | G39: Christian | H39: Christian | I39: Christian
B40: Piçarras | C40: Miguel | D40: Miguel | E40: Miguel | F40: Miguel | G40: Miguel | H40: Miguel | I40: Miguel
B41: Piçarras | C41: Priscila | D41: Priscila | E41: Priscila | F41: Priscila | G41: Priscila | H41: Priscila | I41: Priscila
B42: Piçarras/Penha | C42: Luiz | D42: Luiz | E42: Luiz | F42: Luiz | G42: Luiz | H42: Luiz | I42: Luiz
B43: Piçarras/Penha | C43: Jean | D43: Jean | E43: Jean | F43: Jean | G43: Jean | H43: Jean | I43: Jean
B44: Externo | C44: Diogo | D44: Diogo | E44: Diogo | F44: Diogo | G44: Diogo | H44: Diogo | I44: Diogo
...

Sheet Agosto_21
B3: Dias | C3: Sábado | D3: Domingo | E3: Segunda-feira | F3: Terça-feira | G3: Quarta-feira | H3: Quinta-feira | I3: Sexta-feira
B4: PDV | C4: 44415 | D4: 44416 | E4: 44417 | F4: 44418 | G4: 44419 | H4: 44420 | I4: 44421
B5: Penha | C5: Andressa | D5: Andressa | E5: Andressa | F5: Andressa | G5: Andressa | H5: Andressa | I5: Andressa
B6: Penha | C6: Isadora | D6: Isadora | E6: Isadora | F6: Isadora | G6: Isadora | H6: Isadora | I6: Isadora
B7: Penha | C7: Christian | D7: Christian | E7: Christian | F7: Christian | G7: Christian | H7: Christian | I7: Christian
B8: Piçarras | C8: Emanuele | D8: Emanuele | E8: Emanuele | F8: Emanuele | G8: Emanuele | H8: Emanuele | I8: Emanuele
B9: Piçarras | C9: Miguel | D9: Miguel | E9: Miguel | F9: Miguel | G9: Miguel | H9: Miguel | I9: Miguel
B10: Piçarras | C10: Priscila | D10: Priscila | E10: Priscila | F10: Priscila | G10: Priscila | H10: Priscila | I10: Priscila
B11: Piçarras/Penha | C11: Luiz | D11: Luiz | E11: Luiz | F11: Luiz | G11: Luiz | H11: Luiz | I11: Luiz
B12: Piçarras/Penha | C12: Jean | D12: Jean | E12: Jean | F12: Jean | G12: Jean | H12: Jean | I12: Jean
B13: Externo | C13: Diogo | D13: Diogo | E13: Diogo | F13: Diogo | G13: Diogo | H13: Diogo | I13: Diogo
B15: Dias | C15: Sábado | D15: Domingo | E15: Segunda-feira | F15: Terça-feira | G15: Quarta-feira | H15: Quinta-feira | I15: Sexta-feira
B16: PDV | C16: 44422 | D16: 44423 | E16: 44424 | F16: 44425 | G16: 44426 | H16: 44427 | I16: 44428
B17: Penha | C17: Andressa | D17: Andressa | E17: Andressa | F17: Andressa | G17: Andressa | H17: Andressa | I17: Andressa
B18: Penha | C18: Isadora | D18: Isadora | E18: Isadora | F18: Isadora | G18: Isadora | H18: Isadora | I18: Isadora
B19: Penha | C19: Christian | D19: Christian | E19: Christian | F19: Christian | G19: Christian | H19: Christian | I19: Christian
B20: Piçarras | C20: Emanuele | D20: Emanuele | E20: Emanuele | F20: Emanuele | G20: Emanuele | H20: Emanuele | I20: Emanuele
B21: Piçarras | C21: Miguel | D21: Miguel | E21: Miguel | F21: Miguel | G21: Miguel | H21: Miguel | I21: Miguel
B22: Piçarras | C22: Priscila | D22: Priscila | E22: Priscila | F22: Priscila | G22: Priscila | H22: Priscila | I22: Priscila
B23: Piçarras/Penha | C23: Luiz | D23: Luiz | E23: Luiz | F23: Luiz | G23: Luiz | H23: Luiz | I23: Luiz
B24: Piçarras/Penha | C24: Jean | D24: Jean | E24: Jean | F24: Jean | G24: Jean | H24: Jean | I24: Jean
B25: Externo | C25: Diogo | D25: Diogo | E25: Diogo | F25: Diogo | G25: Diogo | H25: Diogo | I25: Diogo
B27: Dias | C27: Sábado | D27: Domingo | E27: Segunda-feira | F27: Terça-feira | G27: Quarta-feira | H27: Quinta-feira | I27: Sexta-feira
B28: PDV | C28: 44429 | D28: 44430 | E28: 44431 | F28: 44432 | G28: 44433 | H28: 44434 | I28: 44435
B29: Penha | C29: Andressa | D29: Andressa | E29: Andressa | F29: Andressa | G29: Andressa | H29: Andressa | I29: Andressa
B30: Penha | C30: Isadora | D30: Isadora | E30: Isadora | F30: Isadora | G30: Isadora | H30: Isadora | I30: Isadora
B31: Penha | C31: Christian | D31: Christian | E31: Christian | F31: Christian | G31: Christian | H31: Christian | I31: Christian
B32: Piçarras | C32: Emanuele | D32: Emanuele | E32: Emanuele | F32: Emanuele | G32: Emanuele | H32: Emanuele | I32: Emanuele
B33: Piçarras | C33: Miguel | D33: Miguel | E33: Miguel | F33: Miguel | G33: Miguel | H33: Miguel | I33: Miguel
B34: Piçarras | C34: Priscila | D34: Priscila | E34: Priscila | F34: Priscila | G34: Priscila | H34: Priscila | I34: Priscila
B35: Piçarras/Penha | C35: Luiz | D35: Luiz | E35: Luiz | F35: Luiz | G35: Luiz | H35: Luiz | I35: Luiz
B36: Piçarras/Penha | C36: Jean | D36: Jean | E36: Jean | F36: Jean | G36: Jean | H36: Jean | I36: Jean
B37: Externo | C37: Diogo | D37: Diogo | E37: Diogo | F37: Diogo | G37: Diogo | H37: Diogo | I37: Diogo
B39: Dias | C39: Sábado | D39: Domingo | E39: Segunda-feira | F39: Terça-feira | G39: Quarta-feira | H39: Quinta-feira | I39: Sexta-feira
B40: PDV | C40: 44436 | D40: 44437 | E40: 44438 | F40: 44439 | G40: 44440 | H40: 44441 | I40: 44442
B41: Penha | C41: Andressa | D41: Andressa | E41: Andressa | F41: Andressa | G41: Andressa | H41: Andressa | I41: Andressa
B42: Penha | C42: Isadora | D42: Isadora | E42: Isadora | F42: Isadora | G42: Isadora | H42: Isadora | I42: Isadora
B43: Penha | C43: Christian | D43: Christian | E43: Christian | F43: Christian | G43: Christian | H43: Christian | I43: Christian
B44: Piçarras | C44: Emanuele | D44: Emanuele | E44: Emanuele | F44: Emanuele | G44: Emanuele | H44: Emanuele | I44: Emanuele
B45: Piçarras | C45: Miguel | D45: Miguel | E45: Miguel | F45: Miguel | G45: Miguel | H45: Miguel | I45: Miguel
...

Sheet Setembro_21
B3: Dias | C3: Sábado | D3: Domingo | E3: Segunda-feira | F3: Terça-feira | G3: Quarta-feira | H3: Quinta-feira | I3: Sexta-feira
B4: PDV | C4: 44443 | D4: 44444 | E4: 44445 | F4: 44446 | G4: 44447 | H4: 44448 | I4: 44449
B5: Penha | C5: Andressa | D5: Andressa | E5: Andressa | F5: Andressa | G5: Andressa | H5: Andressa | I5: Andressa
B6: Penha | C6: Isadora | D6: Isadora | E6: Isadora | F6: Isadora | G6: Isadora | H6: Isadora | I6: Isadora
B7: Penha | C7: Christian | D7: Christian | E7: Christian | F7: Christian | G7: Christian | H7: Christian | I7: Christian
B8: Piçarras | C8: Janaina | D8: Janaina | E8: Janaina | F8: Janaina | G8: Janaina | H8: Janaina | I8: Janaina
B9: Piçarras | C9: Miguel | D9: Miguel | E9: Miguel | F9: Miguel | G9: Miguel | H9: Miguel | I9: Miguel
B10: Piçarras | C10: Priscila | D10: Priscila | E10: Priscila | F10: Priscila | G10: Priscila | H10: Priscila | I10: Priscila
B11: Piçarras/Penha | C11: Luiz | D11: Luiz | E11: Luiz | F11: Luiz | G11: Luiz | H11: Luiz | I11: Luiz
B12: Piçarras/Penha | C12: Jean | D12: Jean | E12: Jean | F12: Jean | G12: Jean | H12: Jean | I12: Jean
B13: Externo | C13: Diogo | D13: Diogo | E13: Diogo | F13: Diogo | G13: Diogo | H13: Diogo | I13: Diogo
B15: Dias | C15: Sábado | D15: Domingo | E15: Segunda-feira | F15: Terça-feira | G15: Quarta-feira | H15: Quinta-feira | I15: Sexta-feira
B16: PDV | C16: 44450 | D16: 44451 | E16: 44452 | F16: 44453 | G16: 44454 | H16: 44455 | I16: 44456
B17: Penha | C17: Andressa | D17: Andressa | E17: Andressa | F17: Andressa | G17: Andressa | H17: Andressa | I17: Andressa
B18: Penha | C18: Isadora | D18: Isadora | E18: Isadora | F18: Isadora | G18: Isadora | H18: Isadora | I18: Isadora
B19: Penha | C19: Christian | D19: Christian | E19: Christian | F19: Christian | G19: Christian | H19: Christian | I19: Christian
B20: Piçarras | C20: Janaina | D20: Janaina | E20: Janaina | F20: Janaina | G20: Janaina | H20: Janaina | I20: Janaina
B21: Piçarras | C21: Miguel | D21: Miguel | E21: Miguel | F21: Miguel | G21: Miguel | H21: Miguel | I21: Miguel
B22: Piçarras | C22: Priscila | D22: Priscila | E22: Priscila | F22: Priscila | G22: Priscila | H22: Priscila | I22: Priscila
B23: Piçarras/Penha | C23: Luiz | D23: Luiz | E23: Luiz | F23: Luiz | G23: Luiz | H23: Luiz | I23: Luiz
B24: Piçarras/Penha | C24: Jean | D24: Jean | E24: Jean | F24: Jean | G24: Jean | H24: Jean | I24: Jean
B25: Externo | C25: Diogo | D25: Diogo | E25: Diogo | F25: Diogo | G25: Diogo | H25: Diogo | I25: Diogo
B27: Dias | C27: Sábado | D27: Domingo | E27: Segunda-feira | F27: Terça-feira | G27: Quarta-feira | H27: Quinta-feira | I27: Sexta-feira
B28: PDV | C28: 44457 | D28: 44458 | E28: 44459 | F28: 44460 | G28: 44461 | H28: 44462 | I28: 44463
B29: Penha | C29: Andressa | D29: Andressa | E29: Andressa | F29: Andressa | G29: Andressa | H29: Andressa | I29: Andressa
B30: Penha | C30: Isadora | D30: Isadora | E30: Isadora | F30: Isadora | G30: Isadora | H30: Isadora | I30: Isadora
B31: Penha | C31: Christian | D31: Christian | E31: Christian | F31: Christian | G31: Christian | H31: Christian | I31: Christian
B32: Piçarras | C32: Janaina | D32: Janaina | E32: Janaina | F32: Janaina | G32: Janaina | H32: Janaina | I32: Janaina
B33: Piçarras | C33: Miguel | D33: Miguel | E33: Miguel | F33: Miguel | G33: Miguel | H33: Miguel | I33: Miguel
B34: Piçarras | C34: Priscila | D34: Priscila | E34: Priscila | F34: Priscila | G34: Priscila | H34: Priscila | I34: Priscila
B35: Piçarras/Penha | C35: Luiz | D35: Luiz | E35: Luiz | F35: Luiz | G35: Luiz | H35: Luiz | I35: Luiz
B36: Piçarras/Penha | C36: Jean | D36: Jean | E36: Jean | F36: Jean | G36: Jean | H36: Jean | I36: Jean
B37: Externo | C37: Diogo | D37: Diogo | E37: Diogo | F37: Diogo | G37: Diogo | H37: Diogo | I37: Diogo
B39: Dias | C39: Sábado | D39: Domingo | E39: Segunda-feira | F39: Terça-feira | G39: Quarta-feira | H39: Quinta-feira | I39: Sexta-feira
B40: PDV | C40: 44464 | D40: 44465 | E40: 44466 | F40: 44467 | G40: 44468 | H40: 44469 | I40: 44470
B41: Penha | C41: Andressa | D41: Andressa | E41: Andressa | F41: Andressa | G41: Andressa | H41: Andressa | I41: Andressa
B42: Penha | C42: Isadora | D42: Isadora | E42: Isadora | F42: Isadora | G42: Isadora | H42: Isadora | I42: Isadora
B43: Penha | C43: Christian | D43: Christian | E43: Christian | F43: Christian | G43: Christian | H43: Christian | I43: Christian
B44: Piçarras | C44: Janaina | D44: Janaina | E44: Janaina | F44: Janaina | G44: Janaina | H44: Janaina | I44: Janaina
B45: Piçarras | C45: Miguel | D45: Miguel | E45: Miguel | F45: Miguel | G45: Miguel | H45: Miguel | I45: Miguel
...

Sheet Outubro_21
B1: ESCALA DE TRABALHO - OUTUBRO_2021
K2: Eventos do mês
B3: Plantões | C3: Sábado | D3: Domingo | E3: Segunda-feira | F3: Terça-feira | G3: Quarta-feira | H3: Quinta-feira | I3: Sexta-feira | K3: 04/10 - Inicio Luis Gustavo (Coordenador Piçarras)
C4: 44471 | D4: 44472 | E4: 44473 | F4: 44474 | G4: 44475 | H4: 44476 | I4: 44477 | K4: 8, 9 e 10/10 - Agenda de brindes
B5: Penha | C5: Andressa | D5: FOLGA | E5: Andressa | F5: Andressa | G5: Andressa | H5: Andressa | I5: FOLGA | K5: 18/10 - Início Luana, Karla e Mariane
C6: Isadora | D6: FOLGA | E6: FOLGA | F6: Isadora | G6: Isadora | H6: Isadora | I6: Isadora
C7: Christian | D7: Christian | E7: Christian | F7: FOLGA | G7: Christian | H7: Christian | I7: Christian
B8: Piçarras | C8: Janaina | D8: FOLGA | E8: FOLGA | F8: Janaina | G8: Janaina | H8: Janaina | I8: Janaina
C9: Priscila | D9: Priscila | E9: Priscila | F9: Priscila | G9: FOLGA | H9: Priscila | I9: Priscila
C10: Miguel | D10: Miguel | E10: Miguel | F10: FOLGA | G10: Miguel | H10: Miguel | I10: Miguel
E11: Luis Gustavo | F11: Luis Gustavo | G11: Luis Gustavo | H11: Luis Gustavo | I11: Luis Gustavo
B12: Piçarras/Penha | C12: Luiz | D12: Luiz | E12: Luiz | F12: Luiz | G12: FOLGA | H12: Luiz | I12: Luiz
C13: Jean | D13: Jean | E13: FOLGA | F13: Jean | G13: Jean | H13: Jean | I13: Jean
B14: Externo | C14: Diogo | D14: Diogo | E14: FOLGA | F14: Diogo | G14: Diogo | H14: Diogo | I14: Diogo
B15: Plantões | C15: Sábado | D15: Domingo | E15: Segunda-feira | F15: Terça-feira | G15: Quarta-feira | H15: Quinta-feira | I15: Sexta-feira
C16: 44478 | D16: 44479 | E16: 44480 | F16: 44481 | G16: 44482 | H16: 44483 | I16: 44484
B17: Penha | C17: FOLGA | D17: FOLGA | E17: Andressa | F17: Andressa | G17: Andressa | H17: Andressa | I17: Andressa
C18: FOLGA | D18: Isadora | E18: Isadora | F18: FOLGA | G18: Isadora | H18: Isadora | I18: Isadora
C19: Christian | D19: Christian | E19: FOLGA | F19: FOLGA | G19: Christian | H19: Christian | I19: Christian
B20: Piçarras | C20: Janaina | D20: FOLGA | E20: Janaina | F20: FOLGA | G20: Janaina | H20: Janaina | I20: Janaina
C21: Priscila | D21: FOLGA | E21: FOLGA | F21: Priscila | G21: Priscila | H21: Priscila | I21: Priscila
C22: Miguel | D22: Miguel | E22: FOLGA | F22: FOLGA | G22: Miguel | H22: Miguel | I22: Miguel
C23: Luis Gustavo | D23: Luis Gustavo | E23: Luis Gustavo | F23: FOLGA | G23: Luis Gustavo | H23: Luis Gustavo | I23: Luis Gustavo
B24: Piçarras/Penha | C24: Luiz | D24: Luiz | E24: Luiz | F24: Luiz | G24: FOLGA | H24: Luiz | I24: Luiz
C25: Jean | D25: Jean | E25: Jean | F25: FOLGA | G25: Jean | H25: Jean | I25: Jean
B26: Externo | C26: Diogo | D26: FOLGA | E26: FOLGA | F26: Diogo | G26: Diogo | H26: Diogo | I26: Diogo
B27: Plantões | C27: Sábado | D27: Domingo | E27: Segunda-feira | F27: Terça-feira | G27: Quarta-feira | H27: Quinta-feira | I27: Sexta-feira
C28: 44485 | D28: 44486 | E28: 44487 | F28: 44488 | G28: 44489 | H28: 44490 | I28: 44491
B29: Penha | C29: FOLGA | D29: FOLGA | E29: Andressa | F29: Andressa | G29: Andressa | H29: Andressa | I29: Andressa
C30: Isadora | D30: FOLGA | E30: FOLGA | F30: Isadora | G30: Isadora | H30: Isadora | I30: Isadora
E31: Luana | F31: Luana | G31: Luana | H31: Luana | I31: Luana
C32: Christian | D32: Christian | E32: Christian | F32: FOLGA | G32: Christian | H32: Christian | I32: Christian
B33: Piçarras | C33: FOLGA | D33: FOLGA | E33: Janaina | F33: Janaina | G33: Janaina | H33: Janaina | I33: Janaina
C34: Priscila | D34: Priscila | E34: Priscila | F34: Priscila | G34: Priscila | H34: Priscila | I34: Priscila
E35: Karla | F35: Karla | G35: Karla | H35: Karla | I35: Karla
E36: Mariane | F36: Mariane | G36: Mariane | H36: Mariane | I36: Mariane
C37: Miguel | D37: Miguel | E37: Miguel | F37: FOLGA | G37: Miguel | H37: Miguel | I37: Miguel
C38: FOLGA | D38: FOLGA | E38: Luis Gustavo | F38: Luis Gustavo | G38: Luis Gustavo | H38: Luis Gustavo | I38: Luis Gustavo
B39: Piçarras/Penha | C39: Luiz | D39: FOLGA | E39: Luiz | F39: Luiz | G39: Luiz | H39: Luiz | I39: Luiz
C40: Jean | D40: Jean | E40: FOLGA | F40: Jean | G40: Jean | H40: Jean | I40: Jean
...

Sheet Novembro_21
B1: ESCALA DE TRABALHO - NOVEMBRO_2021
K2: Eventos do mês
B3: Plantões | C3: Sábado | D3: Domingo | E3: Segunda-feira | F3: Terça-feira | G3: Quarta-feira | H3: Quinta-feira | I3: Sexta-feira | K3: 44502 | L3: Finados (feriado nacional)
C4: 44499 | D4: 44500 | E4: 44501 | F4: 02/Nov Feriado | G4: 44503 | H4: 44504 | I4: 44505 | K4: 44505 | L4: 10 Anos Vetter
B5: Penha | E5: Andressa | F5: Andressa | G5: Andressa | H5: Andressa | I5: Andressa | K5: 44515 | L5: Proclamação da República (feriado nacional)
D6: FOLGA | E6: FOLGA | F6: Isadora | G6: Isadora | H6: Isadora | I6: FOLGA
C7: FOLGA | E7: Luana | F7: FOLGA | G7: Luana | H7: FOLGA | I7: Luana
E8: Christian | F8: FOLGA | G8: Christian | H8: Christian | I8: Christian
B9: Piçarras | E9: Janaina | F9: FOLGA | G9: Janaina | H9: Janaina | I9: Janaina
D10: FOLGA | E10: FOLGA | F10: Karla | G10: Karla | H10: Karla | I10: FOLGA
C11: FOLGA | E11: Mariane | F11: Mariane | G11: FOLGA | H11: FOLGA | I11: Mariane
E12: Miguel | F12: FOLGA | G12: Miguel | H12: Miguel | I12: Miguel
D13: verificar | E13: verificar | F13: Luis Gustavo | G13: Luis Gustavo | H13: Luis Gustavo | I13: Luis Gustavo
B14: Piçarras/Penha | E14: Luiz | F14: Luiz | G14: Luiz | H14: Luiz | I14: Luiz
E15: Jean | F15: FOLGA | G15: Jean | H15: Jean | I15: Jean
B16: Externo | D16: verificar | E16: verificar | F16: Diogo - Penha | G16: Diogo | H16: Diogo | I16: Diogo
B17: Plantões | C17: Sábado | D17: Domingo | E17: Segunda-feira | F17: Terça-feira | G17: Quarta-feira | H17: Quinta-feira | I17: Sexta-feira
C18: 44506 | D18: 44507 | E18: 44508 | F18: 44509 | G18: 44510 | H18: 44511 | I18: 44512
B19: Penha | C19: FOLGA | D19: FOLGA | E19: Andressa | F19: Andressa | G19: Andressa | H19: Andressa | I19: Andressa
C20: FOLGA | D20: Isadora | E20: Isadora | F20: FOLGA | G20: Isadora | H20: Isadora | I20: Isadora
C21: Luana | D21: FOLGA | E21: FOLGA | F21: Luana | G21: Luana | H21: Luana | I21: Luana
C22: Christian | D22: FOLGA | E22: FOLGA | F22: Christian | G22: Christian | H22: Christian | I22: Christian
B23: Piçarras | C23: FOLGA | D23: FOLGA | E23: Janaina | F23: Janaina | G23: Janaina | H23: Janaina | I23: Janaina
C24: FOLGA | D24: Karla | E24: Karla | F24: FOLGA | G24: Karla | H24: Karla | I24: Karla
C25: Mariane | D25: FOLGA | E25: FOLGA | F25: Mariane | G25: Mariane | H25: Mariane | I25: Mariane
C26: Miguel | D26: FOLGA | E26: FOLGA | F26: Miguel | G26: Miguel | H26: Miguel | I26: Miguel
C27: Luis Gustavo | D27: Luis Gustavo | E27: Luis Gustavo | F27: FOLGA | G27: Luis Gustavo | H27: Luis Gustavo | I27: Luis Gustavo
B28: Piçarras/Penha | C28: FOLGA | D28: FOLGA | E28: Luiz | F28: Luiz | G28: Luiz | H28: Luiz | I28: Luiz
C29: Jean | D29: FOLGA | E29: FOLGA | F29: Jean | G29: Jean | H29: Jean | I29: Jean
B30: Externo | C30: Diogo | D30: Diogo | E30: Diogo | F30: FOLGA | G30: Diogo | H30: Diogo | I30: Diogo
B31: Plantões | C31: Sábado | D31: Domingo | E31: Segunda-feira | F31: Terça-feira | G31: Quarta-feira | H31: Quinta-feira | I31: Sexta-feira
C32: 44513 | D32: 44514 | E32: 15/nov Feriado | F32: 44516 | G32: 44517 | H32: 44518 | I32: 44519
B33: Penha | C33: FOLGA | D33: FOLGA | E33: Andressa | F33: Andressa | G33: Andressa | H33: Andressa | I33: Andressa
C34: Isadora | D34: FOLGA | E34: FOLGA | F34: Isadora | G34: Isadora | H34: FOLGA | I34: Isadora
C35: FOLGA | D35: Luana | E35: Luana | F35: FOLGA | G35: Luana | H35: Luana | I35: FOLGA
C36: Christian | D36: Christian | E36: Christian | F36: FOLGA | G36: Christian | H36: Christian | I36: Christian
B37: Piçarras | C37: FOLGA | D37: FOLGA | E37: FOLGA | F37: Janaina | G37: Janaina | H37: Janaina | I37: Janaina
C38: Karla | D38: FOLGA | E38: FOLGA | F38: Karla | G38: Karla | H38: Karla | I38: Karla
C39: FOLGA | D39: Mariane | E39: Mariane | F39: Mariane | G39: Mariane | H39: FOLGA | I39: FOLGA
C40: Miguel | D40: Miguel | E40: Miguel | F40: FOLGA | G40: Miguel | H40: Miguel | I40: Miguel
...

Sheet Dezembro_21
B1: ESCALA DE TRABALHO - DEZEMBRO_2021
B3: Plantões | C3: Sábado | D3: Domingo | E3: Segunda-feira | F3: Terça-feira | G3: Quarta-feira | H3: Quinta-feira | I3: Sexta-feira | K3: Eventos do mês
G4: 44531 | H4: 44532 | I4: 44533 | K4: 44544 | L4: Aniversário Piçarras
B5: Penha | G5: Andressa | H5: Andressa | I5: Andressa | K5: 44555 | L5: Natal
G6: Isadora | H6: Isadora | I6: Isadora
G7: Luana | H7: Luana | I7: Luana
G8: Christian | H8: Christian | I8: Christian
B9: Piçarras | G9: Karla | H9: Karla | I9: Karla
G10: Mariane | H10: Mariane | I10: Mariane
G11: Miguel | H11: Miguel | I11: Miguel
G12: Luis Gustavo | H12: Luis Gustavo | I12: Luis Gustavo
B13: Piçarras/Penha | G13: Luiz | H13: Luiz | I13: Luiz
G14: Jean | H14: Jean | I14: Jean
B15: Externo | G15: Diogo | H15: Diogo | I15: Diogo
B16: Plantões | C16: Sábado | D16: Domingo | E16: Segunda-feira | F16: Terça-feira | G16: Quarta-feira | H16: Quinta-feira | I16: Sexta-feira
C17: 44534 | D17: 44535 | E17: 44536 | F17: 44537 | G17: 44538 | H17: 44539 | I17: 44540
B18: Penha | C18: FOLGA | D18: FOLGA | E18: Andressa | F18: Andressa | G18: Andressa | H18: Andressa | I18: Andressa
C19: FOLGA | D19: Isadora | E19: Isadora | F19: FOLGA | G19: Isadora | H19: Isadora | I19: Isadora
C20: Luana | D20: FOLGA | E20: FOLGA | F20: Luana | G20: Luana | H20: Luana | I20: Luana
C21: Christian | D21: FOLGA | E21: FOLGA | F21: Christian | G21: Christian | H21: Christian | I21: Christian
B22: Piçarras | C22: FOLGA | D22: FOLGA | E22: Karla | F22: Karla | G22: Karla | H22: Karla | I22: Karla
C23: Mariane | D23: Mariane | E23: FOLGA | F23: FOLGA | G23: Mariane | H23: Mariane | I23: Mariane
C24: Miguel | D24: FOLGA | E24: FOLGA | F24: Miguel | G24: Miguel | H24: Miguel | I24: Miguel
C25: Luis Gustavo | D25: Luis Gustavo | E25: Luis Gustavo | F25: FOLGA | G25: Luis Gustavo | H25: Luis Gustavo | I25: Luis Gustavo
B26: Piçarras/Penha | C26: FOLGA | D26: FOLGA | E26: Luiz | F26: Luiz | G26: Luiz | H26: Luiz | I26: Luiz
C27: Jean | D27: FOLGA | E27: FOLGA | F27: Jean | G27: Jean | H27: Jean | I27: Jean
B28: Externo | C28: Diogo | D28: Diogo | E28: Diogo | F28: FOLGA | G28: Diogo | H28: Diogo | I28: Diogo
B29: Plantões | C29: Sábado | D29: Domingo | E29: Segunda-feira | F29: Terça-feira | G29: Quarta-feira | H29: Quinta-feira | I29: Sexta-feira
C30: 44541 | D30: 44542 | E30: 44543 | F30: 44544 | G30: 44545 | H30: 44546 | I30: 44547
B31: Penha | C31: FOLGA | D31: FOLGA | E31: Andressa | F31: Andressa | G31: Andressa | H31: Andressa | I31: Andressa
C32: Isadora | D32: FOLGA | E32: FOLGA | F32: Isadora | G32: Isadora | H32: Isadora | I32: Isadora
C33: FOLGA | D33: Luana | E33: Luana | F33: FOLGA | G33: Luana | H33: Luana | I33: Luana
C34: Christian | D34: Christian | E34: Christian | F34: FOLGA | G34: Christian | H34: Christian | I34: Christian
B35: Piçarras | C35: Karla | D35: FOLGA | E35: FOLGA | F35: Karla | G35: Karla | H35: Karla | I35: FOLGA
C36: FOLGA | D36: Mariane | E36: Mariane | F36: FOLGA | G36: Mariane | H36: FOLGA | I36: Mariane
C37: Miguel | D37: Miguel | E37: Miguel | F37: FOLGA | G37: Miguel | H37: Miguel | I37: Miguel
C38: Luis Gustavo | D38: FOLGA | E38: FOLGA | F38: Luis Gustavo | G38: Luis Gustavo | H38: Luis Gustavo | I38: Luis Gustavo
B39: Piçarras/Penha | C39: FOLGA | D39: FOLGA | E39: Luiz | F39: Luiz | G39: Luiz | H39: Luiz | I39: Luiz
C40: Jean | D40: Jean | E40: Jean | F40: FOLGA | G40: Jean | H40: Jean | I40: Jean
B41: Externo | C41: Diogo | D41: FOLGA | E41: FOLGA | F41: Diogo | G41: Diogo | H41: Diogo | I41: Diogo
...

Sheet Janeiro_22
B1: ESCALA DE TRABALHO - JANEIRO_2022
B2: Plantões | C2: Sábado | D2: Domingo | E2: Segunda-feira | F2: Terça-feira | G2: Quarta-feira | H2: Quinta-feira | I2: Sexta-feira
C3: 44562 | D3: 44563 | E3: 44564 | F3: 44565 | G3: 44566 | H3: 44567 | I3: 44568
B4: Penha | C4: ANDRESSA | D4: ANDRESSA | E4: Andressa | F4: Andressa | G4: Andressa | H4: Andressa | I4: Andressa
C5: ISADORA | D5: Isadora | E5: Isadora | F5: ISADORA | G5: ISADORA | H5: Isadora | I5: Isadora
C6: LUANA | D6: LUANA | E6: LUANA | F6: Luana | G6: Luana | H6: LUANA | I6: Luana
C7: CHRISTIAN | D7: CHRISTIAN | E7: CHRISTIAN | F7: Christian | G7: Christian | H7: Christian | I7: Christian
B8: Piçarras | C8: KARLA | D8: Karla | E8: Karla | F8: KARLA | G8: KARLA | H8: Karla | I8: Karla
C9: MARIANE | D9: MARIANE | E9: MARIANE | F9: Mariane | G9: Mariane | H9: MARIANE | I9: Mariane
D10: - | E10: - | F10: - | G10: - | H10: - | I10: -
B11: Piçarras/Penha | C11: LUIZ | D11: LUIZ | E11: Luiz | F11: Luiz | G11: Luiz | H11: Luiz | I11: Luiz
C12: DIOGO | D12: Diogo | E12: Diogo | F12: DIOGO | G12: Diogo | H12: Diogo | I12: Diogo
B13: Externo | C13: MIGUEL | D13: MIGUEL | E13: MIGUEL | F13: Miguel | G13: Miguel | H13: Miguel | I13: Miguel
B14: Plantões | C14: Sábado | D14: Domingo | E14: Segunda-feira | F14: Terça-feira | G14: Quarta-feira | H14: Quinta-feira | I14: Sexta-feira
C15: 44204 | D15: 44205 | E15: 44206 | F15: 44207 | G15: 44208 | H15: 44209 | I15: 44210
B16: Penha | C16: ANDRESSA | D16: ANDRESSA | E16: Andressa | F16: Andressa | G16: Andressa | H16: Andressa | I16: Andressa
C17: Isadora | D17: ISADORA | E17: ISADORA | F17: Isadora | G17: Isadora | H17: Isadora | I17: Isadora
C18: LUANA | D18: Luana | E18: Luana | F18: LUANA | G18: Luana | H18: Luana | I18: Luana
C19: Christian | D19: Christian | E19: Christian | F19: CHRISTIAN | G19: Christian | H19: Christian | I19: Christian
B20: Piçarras | C20: Karla | D20: KARLA | E20: KARLA | F20: Karla | G20: Karla | H20: Karla | I20: Karla
C21: MARIANE | D21: Mariane | E21: Mariane | F21: MARIANE | G21: Mariane | H21: Mariane | I21: Mariane
E22: Roberto | F22: Roberto | G22: Roberto | H22: Roberto | I22: Roberto
B23: Piçarras/Penha | C23: LUIZ | D23: LUIZ | E23: Luiz | F23: Luiz | G23: Luiz | H23: Luiz | I23: Luiz
C24: Diogo | D24: DIOGO | E24: DIOGO | F24: Diogo | G24: Diogo | H24: Diogo | I24: Diogo
B25: Externo | C25: Miguel | D25: Miguel | E25: Miguel | F25: MIGUEL | G25: Miguel | H25: Miguel | I25: Miguel
B26: Plantões | C26: Sábado | D26: Domingo | E26: Segunda-feira | F26: Terça-feira | G26: Quarta-feira | H26: Quinta-feira | I26: Sexta-feira
C27: 44211 | D27: 44212 | E27: 44213 | F27: 44214 | G27: 44215 | H27: 44216 | I27: 44217
B28: Penha | C28: ANDRESSA | D28: ANDRESSA | E28: Andressa | F28: Andressa | G28: Andressa | H28: Andressa | I28: Andressa
C29: ISADORA | D29: Isadora | E29: Isadora | F29: ISADORA | G29: Isadora | H29: Isadora | I29: Isadora
C30: Luana | D30: LUANA | E30: LUANA | F30: Luana | G30: Luana | H30: Luana | I30: Luana
C31: Christian | D31: CHRISTIAN | E31: CHRISTIAN | F31: Christian | G31: Christian | H31: Christian | I31: Christian
B32: Piçarras | C32: KARLA | D32: Karla | E32: Karla | F32: KARLA | G32: Karla | H32: Karla | I32: Karla
C33: Mariane | D33: MARIANE | E33: MARIANE | F33: Mariane | G33: Mariane | H33: Mariane | I33: Mariane
C34: Roberto | D34: Roberto | E34: Roberto | F34: ROBERTO | G34: Roberto | H34: Roberto | I34: Roberto
B35: Piçarras/Penha | C35: LUIZ | D35: LUIZ | E35: Luiz | F35: Luiz | G35: Luiz | H35: Luiz | I35: Luiz
C36: Diogo | D36: Diogo | E36: Diogo | F36: DIOGO | G36: Diogo | H36: Diogo | I36: Diogo
B37: Externo | C37: Miguel | D37: MIGUEL | E37: MIGUEL | F37: Miguel | G37: Miguel | H37: Miguel | I37: Miguel
B38: Plantões | C38: Sábado | D38: Domingo | E38: Segunda-feira | F38: Terça-feira | G38: Quarta-feira | H38: Quinta-feira | I38: Sexta-feira
C39: 44218 | D39: 44219 | E39: 44220 | F39: 44221 | G39: 44222 | H39: 44223 | I39: 44224
B40: Penha | C40: ANDRESSA | D40: ANDRESSA | E40: Andressa | F40: Andressa | G40: Andressa | H40: Andressa | I40: Andressa
...

Sheet Fevereiro_22
B1: ESCALA DE TRABALHO - FEVEREIRO_2022
B2: Plantões | C2: Sábado | D2: Domingo | E2: Segunda-feira | F2: Terça-feira | G2: Quarta-feira | H2: Quinta-feira | I2: Sexta-feira
F3: 44593 | G3: 44594 | H3: 44595 | I3: 44596
B4: Penha | F4: Andressa | G4: Andressa | H4: Andressa | I4: Andressa
F5: ISADORA | G5: Isadora | H5: Isadora | I5: Isadora
F6: Luana | G6: Luana | H6: Luana | I6: Luana
F7: Christian | G7: Christian | H7: Christian | I7: Christian
B8: Piçarras | F8: KARLA | G8: Karla | H8: Karla | I8: Karla
F9: Mariane | G9: Mariane | H9: Mariane | I9: Mariane
F10: ROBERTO | G10: Roberto | H10: Roberto | I10: Roberto
B11: Piçarras/Penha | F11: Luiz | G11: Luiz | H11: Luiz | I11: Luiz
F12: DIOGO | G12: Diogo | H12: Diogo | I12: Diogo
B13: Externo | F13: Miguel | G13: Miguel | H13: Miguel | I13: Miguel
B14: Plantões | C14: Sábado | D14: Domingo | E14: Segunda-feira | F14: Terça-feira | G14: Quarta-feira | H14: Quinta-feira | I14: Sexta-feira
C15: 44597 | D15: 44598 | E15: 44599 | F15: 44600 | G15: 44601 | H15: 44602 | I15: 44603
B16: Penha | C16: ANDRESSA | D16: ANDRESSA | E16: Andressa | F16: Andressa | G16: Andressa | H16: Andressa | I16: Andressa
C17: Isadora | D17: ISADORA | E17: ISADORA | F17: Isadora | G17: Isadora | H17: Isadora | I17: Isadora
C18: LUANA | D18: Luana | E18: Luana | F18: LUANA | G18: Luana | H18: Luana | I18: Luana
C19: Christian | D19: Christian | E19: Christian | F19: CHRISTIAN | G19: Christian | H19: Christian | I19: Christian
B20: Piçarras | C20: Karla | D20: KARLA | E20: KARLA | F20: Karla | G20: Karla | H20: Karla | I20: Karla
C21: MARIANE | D21: Mariane | E21: Mariane | F21: MARIANE | G21: Mariane | H21: Mariane | I21: Mariane
C22: Roberto | D22: ROBERTO | E22: ROBERTO | F22: Roberto | G22: Roberto | H22: Roberto | I22: Roberto
B23: Piçarras/Penha | C23: LUIZ | D23: LUIZ | E23: Luiz | F23: Luiz | G23: Luiz | H23: Luiz | I23: Luiz
C24: Diogo | D24: DIOGO | E24: DIOGO | F24: Diogo | G24: Diogo | H24: Diogo | I24: Diogo
B25: Externo | C25: Miguel | D25: Miguel | E25: Miguel | F25: MIGUEL | G25: Miguel | H25: Miguel | I25: Miguel
B26: Plantões | C26: Sábado | D26: Domingo | E26: Segunda-feira | F26: Terça-feira | G26: Quarta-feira | H26: Quinta-feira | I26: Sexta-feira
C27: 44604 | D27: 44605 | E27: 44606 | F27: 44607 | G27: 44608 | H27: 44609 | I27: 44610
B28: Penha | C28: ANDRESSA | D28: ANDRESSA | E28: Andressa | F28: Andressa | G28: Andressa | H28: Andressa | I28: Andressa
C29: ISADORA | D29: Isadora | E29: Isadora | F29: ISADORA | G29: Isadora | H29: Isadora | I29: Isadora
C30: Luana | D30: LUANA | E30: LUANA | F30: Luana | G30: Luana | H30: Luana | I30: Luana
C31: Christian | D31: CHRISTIAN | E31: CHRISTIAN | F31: Christian | G31: Christian | H31: Christian | I31: Christian
B32: Piçarras | C32: KARLA | D32: Karla | E32: Karla | F32: KARLA | G32: Karla | H32: Karla | I32: Karla
C33: Mariane | D33: MARIANE | E33: MARIANE | F33: Mariane | G33: Mariane | H33: Mariane | I33: Mariane
I34: Iara
C35: Roberto | D35: Roberto | E35: Roberto | F35: ROBERTO | G35: Roberto | H35: Roberto | I35: Roberto
B36: Piçarras/Penha | C36: LUIZ | D36: LUIZ | E36: Luiz | F36: Luiz | G36: Luiz | H36: Luiz | I36: Luiz
C37: Diogo | D37: Diogo | E37: Diogo | F37: DIOGO | G37: Diogo | H37: Diogo | I37: Diogo
B38: Externo | C38: Miguel | D38: MIGUEL | E38: MIGUEL | F38: Miguel | G38: Miguel | H38: Miguel | I38: Miguel
B39: Plantões | C39: Sábado | D39: Domingo | E39: Segunda-feira | F39: Terça-feira | G39: Quarta-feira | H39: Quinta-feira | I39: Sexta-feira
C40: 44611 | D40: 44612 | E40: 44613 | F40: 44614 | G40: 44615 | H40: 44616 | I40: 44617
...

Sheet Março_22
B1: ESCALA DE TRABALHO - MARÇO_2022
B2: Plantões | C2: Sábado | D2: Domingo | E2: Segunda-feira | F2: Terça-feira | G2: Quarta-feira | H2: Quinta-feira | I2: Sexta-feira
F3: 44621 | G3: 44622 | H3: 44623 | I3: 44624
B4: Penha | F4: Andressa | G4: Andressa | H4: Andressa | I4: Andressa
F5: ISADORA | G5: Isadora | H5: Isadora | I5: Isadora
F6: Luana | G6: Luana | H6: Luana | I6: Luana
F7: Christian | G7: Christian | H7: Christian | I7: Christian
B8: Piçarras | F8: KARLA | G8: Karla | H8: Karla | I8: Karla
F9: Mariane | G9: Mariane | H9: Mariane | I9: Mariane
F10: Iara | G10: Iara | H10: Iara | I10: Iara
F11: ROBERTO | G11: Roberto | H11: Roberto | I11: Roberto
B12: Piçarras/Penha | F12: Luiz | G12: Luiz | H12: Luiz | I12: Luiz
F13: DIOGO | G13: Diogo | H13: Diogo | I13: Diogo
B14: Externo | F14: Miguel | G14: Miguel | H14: Miguel | I14: Miguel
B15: Plantões | C15: Sábado | D15: Domingo | E15: Segunda-feira | F15: Terça-feira | G15: Quarta-feira | H15: Quinta-feira | I15: Sexta-feira
C16: 44625 | D16: 44626 | E16: 44627 | F16: 44628 | G16: 44629 | H16: 44630 | I16: 44631
B17: Penha | C17: ANDRESSA | D17: ANDRESSA | E17: Andressa | F17: Andressa | G17: Andressa | H17: Andressa | I17: Andressa
C18: Isadora | D18: ISADORA | E18: ISADORA | F18: Isadora | G18: Isadora | H18: Isadora | I18: Isadora
C19: LUANA | D19: Luana | E19: Luana | F19: LUANA | G19: Luana | H19: Luana | I19: Luana
C20: Christian | D20: Christian | E20: Christian | F20: CHRISTIAN | G20: Christian | H20: Christian | I20: Christian
B21: Piçarras | C21: Karla | D21: KARLA | E21: KARLA | F21: Karla | G21: Karla | H21: Karla | I21: Karla
C22: MARIANE | D22: Mariane | E22: Mariane | F22: MARIANE | G22: Mariane | H22: Mariane | I22: Mariane
C23: Iara | D23: Iara | E23: Iara | F23: IARA | G23: Iara | H23: Iara | I23: Iara
C24: Roberto | D24: ROBERTO | E24: ROBERTO | F24: Roberto | G24: Roberto | H24: Roberto | I24: Roberto
B25: Piçarras/Penha | C25: LUIZ | D25: LUIZ | E25: Luiz | F25: Luiz | G25: Luiz | H25: Luiz | I25: Luiz
C26: Diogo | D26: DIOGO | E26: DIOGO | F26: Diogo | G26: Diogo | H26: Diogo | I26: Diogo
B27: Externo | C27: Miguel | D27: Miguel | E27: Miguel | F27: MIGUEL | G27: Miguel | H27: Miguel | I27: Miguel
B28: Plantões | C28: Sábado | D28: Domingo | E28: Segunda-feira | F28: Terça-feira | G28: Quarta-feira | H28: Quinta-feira | I28: Sexta-feira
C29: 44632 | D29: 44633 | E29: 44634 | F29: 44635 | G29: 44636 | H29: 44637 | I29: 44638
B30: Penha | C30: ANDRESSA | D30: ANDRESSA | E30: Andressa | F30: Andressa | G30: Andressa | H30: Andressa | I30: Andressa
C31: ISADORA | D31: Isadora | E31: Isadora | F31: ISADORA | G31: Isadora | H31: Isadora | I31: Isadora
C32: Luana | D32: LUANA | E32: LUANA | F32: Luana | G32: Luana | H32: Luana | I32: Luana
C33: Christian | D33: CHRISTIAN | E33: CHRISTIAN | F33: Christian | G33: Christian | H33: Christian | I33: Christian
B34: Piçarras | C34: KARLA | D34: Karla | E34: Karla | F34: KARLA | G34: Karla | H34: Karla | I34: Karla
C35: Mariane | D35: MARIANE | E35: MARIANE | F35: Mariane | G35: Mariane | H35: Mariane | I35: Mariane
C36: Iara | D36: IARA | E36: IARA | F36: Iara | G36: Iara | H36: Iara | I36: Iara
C37: Roberto | D37: Roberto | E37: Roberto | F37: ROBERTO | G37: Roberto | H37: Roberto | I37: Roberto
B38: Piçarras/Penha | C38: LUIZ | D38: LUIZ | E38: Luiz | F38: Luiz | G38: Luiz | H38: Luiz | I38: Luiz
C39: Diogo | D39: Diogo | E39: Diogo | F39: DIOGO | G39: Diogo | H39: Diogo | I39: Diogo
B40: Externo | C40: Miguel | D40: MIGUEL | E40: MIGUEL | F40: Miguel | G40: Miguel | H40: Miguel | I40: Miguel
...

Sheet Abril_22
B1: ESCALA DE TRABALHO - ABRIL_2022
B2: Plantões | C2: Sábado | D2: Domingo | E2: Segunda-feira | F2: Terça-feira | G2: Quarta-feira | H2: Quinta-feira | I2: Sexta-feira
I3: 44652
B4: Penha | I4: Andressa
I5: Isadora
I6: Christian
B7: Piçarras | I7: Karla
I8: Iara
I9: Roberto
B10: Piçarras/Penha | I10: Luiz
I11: Diogo
B12: Externo | I12: Miguel
B13: Plantões | C13: Sábado | D13: Domingo | E13: Segunda-feira | F13: Terça-feira | G13: Quarta-feira | H13: Quinta-feira | I13: Sexta-feira
C14: 44653 | D14: 44654 | E14: 44655 | F14: 44656 | G14: 44657 | H14: 44658 | I14: 44659
B15: Penha | C15: Andressa | D15: ANDRESSA | E15: Andressa | F15: Andressa | G15: Andressa | H15: Andressa | I15: Andressa
C16: Isadora | D16: ISADORA | E16: ISADORA | F16: Isadora | G16: Isadora | H16: Isadora | I16: Isadora
C17: Christian | D17: Christian | E17: Christian | F17: CHRISTIAN | G17: Christian | H17: Christian | I17: Christian
B18: Piçarras | C18: KARLA | D18: Karla | E18: Karla | F18: KARLA | G18: Karla | H18: Karla | I18: Karla
C19: Iara | D19: Iara | E19: Iara | F19: IARA | G19: Iara | H19: Iara | I19: Iara
C20: Roberto | D20: ROBERTO | E20: ROBERTO | F20: Roberto | G20: Roberto | H20: Roberto | I20: Roberto
B21: Piçarras/Penha | C21: Luiz | D21: LUIZ | E21: Luiz | F21: Luiz | G21: Luiz | H21: Luiz | I21: Luiz
C22: Diogo | D22: DIOGO | E22: DIOGO | F22: Diogo | G22: Diogo | H22: Diogo | I22: Diogo
B23: Externo | C23: Miguel | D23: Miguel | E23: Miguel | F23: MIGUEL | G23: Miguel | H23: Miguel | I23: Miguel
B24: Plantões | C24: Sábado | D24: Domingo | E24: Segunda-feira | F24: Terça-feira | G24: Quarta-feira | H24: Quinta-feira | I24: Sexta-feira
C25: 44660 | D25: 44661 | E25: 44662 | F25: 44663 | G25: 44664 | H25: 44665 | I25: 44666
B26: Penha | C26: ANDRESSA | D26: ANDRESSA | E26: Andressa | F26: Andressa | G26: Andressa | H26: Andressa | I26: Andressa
C27: ISADORA | D27: Isadora | E27: Isadora | F27: ISADORA | G27: Isadora | H27: Isadora | I27: Isadora
C28: Christian | D28: CHRISTIAN | E28: CHRISTIAN | F28: Christian | G28: Christian | H28: Christian | I28: Christian
B29: Piçarras | C29: Karla | D29: KARLA | E29: KARLA | F29: Karla | G29: Karla | H29: Karla | I29: Karla
C30: Iara | D30: IARA | E30: IARA | F30: Iara | G30: Iara | H30: Iara | I30: Iara
C31: Roberto | D31: Roberto | E31: Roberto | F31: ROBERTO | G31: Roberto | H31: Roberto | I31: Roberto
B32: Piçarras/Penha | C32: LUIZ | D32: LUIZ | E32: Luiz | F32: Luiz | G32: Luiz | H32: Luiz | I32: Luiz
C33: Diogo | D33: Diogo | E33: Diogo | F33: DIOGO | G33: Diogo | H33: Diogo | I33: Diogo
B34: Externo | C34: Miguel | D34: MIGUEL | E34: MIGUEL | F34: Miguel | G34: Miguel | H34: Miguel | I34: Miguel
B35: Plantões | C35: Sábado | D35: Domingo | E35: Segunda-feira | F35: Terça-feira | G35: Quarta-feira | H35: Quinta-feira | I35: Sexta-feira
C36: 44667 | D36: 44668 | E36: 44669 | F36: 44670 | G36: 44671 | H36: 44672 | I36: 44673
B37: Penha | C37: ANDRESSA | D37: ANDRESSA | E37: Andressa | F37: Andressa | G37: Andressa | H37: Andressa | I37: Andressa
C38: Isadora | D38: ISADORA | E38: ISADORA | F38: Isadora | G38: Isadora | H38: Isadora | I38: ISADORA
C39: Christian | D39: Christian | E39: Christian | F39: CHRISTIAN | G39: Christian | H39: Christian | I39: Christian
B40: Piçarras | C40: KARLA | D40: Karla | E40: Karla | F40: KARLA | G40: KARLA | H40: Karla | I40: Karla
...

Sheet Maio_22
B1: ESCALA DE TRABALHO - MAIO_2022
B2: Plantões | C2: Sábado | D2: Domingo | E2: Segunda-feira | F2: Terça-feira | G2: Quarta-feira | H2: Quinta-feira | I2: Sexta-feira
D3: 44682 | E3: 44683 | F3: 44684 | G3: 44685 | H3: 44686 | I3: 44687
B4: Penha | D4: ANDRESSA | E4: Andressa | F4: Andressa | G4: Andressa | H4: Andressa | I4: Andressa
D5: ISADORA | E5: ISADORA | F5: Isadora | G5: Isadora | H5: Isadora | I5: Isadora
D6: ANDRIELE | E6: Andriele | F6: Andriele | G6: Andriele | H6: Andriele | I6: Andriele
D7: Christian | E7: Christian | F7: CHRISTIAN | G7: Christian | H7: Christian | I7: Christian
B8: Piçarras | D8: KARLA | E8: Karla | F8: KARLA | G8: Karla | H8: Karla | I8: Karla
D9: LAURA | E9: Laura | F9: LAURA | G9: Laura | H9: Laura | I9: Laura
D10: Iara | E10: Iara | F10: IARA | G10: Iara | H10: Iara | I10: Iara
D11: ROBERTO | E11: ROBERTO | F11: Roberto | G11: Roberto | H11: Roberto | I11: Roberto
B12: Piçarras/Penha | D12: LUIZ | E12: Luiz | F12: Luiz | G12: Luiz | H12: Luiz | I12: Luiz
D13: DIOGO | E13: DIOGO | F13: Diogo | G13: Diogo | H13: Diogo | I13: Diogo
B14: Externo | D14: Miguel | E14: Miguel | F14: MIGUEL | G14: Miguel | H14: Miguel | I14: Miguel
B15: Plantões | C15: Sábado | D15: Domingo | E15: Segunda-feira | F15: Terça-feira | G15: Quarta-feira | H15: Quinta-feira | I15: Sexta-feira
C16: 44688 | D16: 44689 | E16: 44690 | F16: 44691 | G16: 44692 | H16: 44693 | I16: 44694
B17: Penha | C17: ANDRESSA | D17: ANDRESSA | E17: Andressa | F17: Andressa | G17: Andressa | H17: Andressa | I17: Andressa
C18: ISADORA | D18: Isadora | E18: Isadora | F18: ISADORA | G18: Isadora | H18: Isadora | I18: Isadora
C19: ANDRIELE | D19: ANDRIELE | E19: Andriele | F19: Andriele | G19: Andriele | H19: Andriele | I19: Andriele
C20: Christian | D20: CHRISTIAN | E20: CHRISTIAN | F20: Christian | G20: Christian | H20: Christian | I20: Christian
B21: Piçarras | C21: Karla | D21: KARLA | E21: KARLA | F21: Karla | G21: Karla | H21: Karla | I21: Karla
C22: Laura | D22: LAURA | E22: LAURA | F22: Laura | G22: Laura | H22: Laura | I22: Laura
C23: Iara | D23: IARA | E23: IARA | F23: Iara | G23: Iara | H23: Iara | I23: Iara
C24: Roberto | D24: Roberto | E24: Roberto | F24: ROBERTO | G24: Roberto | H24: Roberto | I24: Roberto
B25: Piçarras/Penha | C25: LUIZ | D25: LUIZ | E25: Luiz | F25: Luiz | G25: Luiz | H25: Luiz | I25: Luiz
C26: Diogo | D26: Diogo | E26: Diogo | F26: DIOGO | G26: Diogo | H26: Diogo | I26: Diogo
B27: Externo | C27: Miguel | D27: MIGUEL | E27: MIGUEL | F27: Miguel | G27: Miguel | H27: Miguel | I27: Miguel
B28: Plantões | C28: Sábado | D28: Domingo | E28: Segunda-feira | F28: Terça-feira | G28: Quarta-feira | H28: Quinta-feira | I28: Sexta-feira
C29: 44695 | D29: 44696 | E29: 44697 | F29: 44698 | G29: 44699 | H29: 44700 | I29: 44701
B30: Penha | C30: ANDRESSA | D30: ANDRESSA | E30: Andressa | F30: Andressa | G30: Andressa | H30: Andressa | I30: Andressa
C31: Isadora | D31: ISADORA | E31: ISADORA | F31: Isadora | G31: Isadora | H31: Isadora | I31: Isadora
C32: ANDRIELE | D32: ANDRIELE | E32: Andriele | F32: Andriele | G32: Andriele | H32: Andriele | I32: Andriele
C33: Christian | D33: Christian | E33: Christian | F33: CHRISTIAN | G33: Christian | H33: Christian | I33: Christian
B34: Piçarras | C34: KARLA | D34: Karla | E34: Karla | F34: KARLA | G34: Karla | H34: Karla | I34: Karla
C35: LAURA | D35: Laura | E35: Laura | F35: LAURA | G35: Laura | H35: Laura | I35: Laura
C36: Iara | D36: Iara | E36: Iara | F36: IARA | G36: Iara | H36: Iara | I36: Iara
C37: Roberto | D37: ROBERTO | E37: ROBERTO | F37: Roberto | G37: Roberto | H37: Roberto | I37: Roberto
B38: Piçarras/Penha | C38: LUIZ | D38: LUIZ | E38: Luiz | F38: Luiz | G38: Luiz | H38: Luiz | I38: Luiz
C39: Diogo | D39: DIOGO | E39: DIOGO | F39: Diogo | G39: Diogo | H39: Diogo | I39: Diogo
B40: Externo | C40: Miguel | D40: Miguel | E40: Miguel | F40: MIGUEL | G40: Miguel | H40: Miguel | I40: Miguel
...

Sheet Junho_22
A1: ESCALA DE TRABALHO - JUNHO_2022
A2: Plantões | B2: Sábado | C2: Domingo | D2: Segunda-feira | E2: Terça-feira | F2: Quarta-feira | G2: Quinta-feira | H2: Sexta-feira
F3: 44713 | G3: 44714 | H3: 44715
A4: Penha | F4: Andressa | G4: Andressa | H4: Andressa
F5: Isadora | G5: Isadora | H5: Isadora
F6: Andriele | G6: Andriele | H6: Andriele
A7: Piçarras | F7: Karla | G7: Karla | H7: Karla
F8: Laura | G8: Laura | H8: Laura
F9: Iara | G9: Iara | H9: Iara
F10: Roberto | G10: Roberto | H10: Roberto
A11: Piçarras/Penha | F11: Luiz | G11: Luiz | H11: Luiz
F12: Diogo | G12: Diogo | H12: Diogo
A13: Externo | F13: Miguel | G13: Miguel | H13: Miguel
A14: Plantões | B14: Sábado | C14: Domingo | D14: Segunda-feira | E14: Terça-feira | F14: Quarta-feira | G14: Quinta-feira | H14: Sexta-feira
B15: 44716 | C15: 44717 | D15: 44718 | E15: 44719 | F15: 44720 | G15: 44721 | H15: 44722
A16: Penha | B16: ANDRESSA | C16: ANDRESSA | D16: Andressa | E16: Andressa | F16: Andressa | G16: Andressa | H16: Andressa
B17: ISADORA | C17: Isadora | D17: Isadora | E17: ISADORA | F17: Isadora | G17: Isadora | H17: Isadora
B18: ANDRIELE | C18: ANDRIELE | D18: Andriele | E18: Andriele | F18: Andriele | G18: Andriele | H18: Andriele
A19: Piçarras | B19: Karla | C19: KARLA | D19: KARLA | E19: Karla | F19: Karla | G19: Karla | H19: Karla
B20: LAURA | C20: Laura | D20: Laura | E20: LAURA | F20: Laura | G20: Laura | H20: Laura
B21: Iara | C21: IARA | D21: IARA | E21: Iara | F21: Iara | G21: Iara | H21: Iara
B22: Roberto | C22: Roberto | D22: Roberto | E22: ROBERTO | F22: Roberto | G22: Roberto | H22: Roberto
A23: Piçarras/Penha | B23: LUIZ | C23: LUIZ | D23: Luiz | E23: Luiz | F23: Luiz | G23: Luiz | H23: Luiz
B24: Diogo | C24: Diogo | D24: Diogo | E24: DIOGO | F24: Diogo | G24: Diogo | H24: Diogo
A25: Externo | B25: Miguel | C25: MIGUEL | D25: MIGUEL | E25: Miguel | F25: Miguel | G25: Miguel | H25: Miguel
A26: Plantões | B26: Sábado | C26: Domingo | D26: Segunda-feira | E26: Terça-feira | F26: Quarta-feira | G26: Quinta-feira | H26: Sexta-feira
B27: 44723 | C27: 44724 | D27: 44725 | E27: 44726 | F27: 44727 | G27: 44728 | H27: 44729
A28: Penha | B28: ANDRESSA | C28: ANDRESSA | D28: Andressa | E28: Andressa | F28: Andressa | G28: Andressa | H28: ANDRESSA
B29: Isadora | C29: ISADORA | D29: ISADORA | E29: Isadora | F29: Isadora | G29: Isadora | H29: ISADORA
E30: Andréia | F30: Andréia | G30: ANDRÉIA | H30: Andréia
B31: ANDRIELE | C31: ANDRIELE | D31: Andriele | E31: Andriele | F31: Andriele | G31: ANDRIELE | H31: Andriele
A32: Piçarras | B32: KARLA | C32: Karla | D32: Karla | E32: KARLA | F32: KARLA | G32: Karla | H32: Karla
B33: Laura | C33: LAURA | D33: LAURA | E33: Laura | F33: Laura | G33: LAURA | H33: Laura
B34: Iara | C34: Iara | D34: Iara | E34: IARA | F34: Iara | G34: Iara | H34: Iara
B35: Roberto | C35: ROBERTO | D35: ROBERTO | E35: Roberto | F35: Roberto | G35: Roberto | H35: Roberto
A36: Piçarras/Penha | B36: LUIZ | C36: LUIZ | D36: Luiz | E36: Luiz | F36: Luiz | G36: Luiz | H36: Luiz
B37: Diogo | C37: DIOGO | D37: DIOGO | E37: Diogo | F37: Diogo | G37: Diogo | H37: Diogo
A38: Externo | B38: Miguel | C38: Miguel | D38: Miguel | E38: MIGUEL | F38: Miguel | G38: Miguel | H38: Miguel
A39: Plantões | B39: Sábado | C39: Domingo | D39: Segunda-feira | E39: Terça-feira | F39: Quarta-feira | G39: Quinta-feira | H39: Sexta-feira
B40: 44730 | C40: 44731 | D40: 44732 | E40: 44733 | F40: 44734 | G40: 44735 | H40: 44736
...

Sheet Julho_22
A1: ESCALA DE TRABALHO - JULHO_2022
A2: Plantões | B2: Sábado | C2: Domingo | D2: Segunda-feira | E2: Terça-feira | F2: Quarta-feira | G2: Quinta-feira | H2: Sexta-feira
H3: 44743
A4: Penha | H4: Andressa
H5: Isadora
H6: Andréia
H7: Andriele
A8: Piçarras | H8: Karla
H9: Laura
H10: Iara
H11: Roberto
A12: Piçarras/Penha | H12: Luiz
H13: Diogo
A14: Externo | H14: Miguel
A15: Plantões | B15: Sábado | C15: Domingo | D15: Segunda-feira | E15: Terça-feira | F15: Quarta-feira | G15: Quinta-feira | H15: Sexta-feira
B16: 44744 | C16: 44745 | D16: 44746 | E16: 44747 | F16: 44748 | G16: 44749 | H16: 44750
A17: Penha | B17: ANDRESSA | C17: ANDRESSA | D17: Andressa | E17: Andressa | F17: Andressa | G17: Andressa | H17: Andressa
B18: ISADORA | C18: Isadora | D18: Isadora | E18: ISADORA | F18: Isadora | G18: Isadora | H18: Isadora
B19: Andréia | C19: ANDRÉIA | D19: ANDRÉIA | E19: Andréia | F19: Andréia | G19: Andréia | H19: Andréia
B20: ANDRIELE | C20: ANDRIELE | D20: Andriele | E20: Andriele | F20: Andriele | G20: Andriele | H20: Andriele
A21: Piçarras | B21: Karla | C21: KARLA | D21: KARLA | E21: Karla | F21: Karla | G21: Karla | H21: Karla
B22: LAURA | C22: Laura | D22: Laura | E22: LAURA | F22: Laura | G22: Laura | H22: Laura
B23: Iara | C23: IARA | D23: IARA | E23: Iara | F23: Iara | G23: Iara | H23: Iara
B24: Roberto | C24: Roberto | D24: Roberto | E24: ROBERTO | F24: Roberto | G24: Roberto | H24: Roberto
A25: Piçarras/Penha | B25: LUIZ | C25: LUIZ | D25: Luiz | E25: Luiz | F25: Luiz | G25: Luiz | H25: Luiz
B26: Diogo | C26: Diogo | D26: Diogo | E26: DIOGO | F26: Diogo | G26: Diogo | H26: Diogo
A27: Externo | B27: Miguel | C27: MIGUEL | D27: MIGUEL | E27: Miguel | F27: Miguel | G27: Miguel | H27: Miguel
A28: Plantões | B28: Sábado | C28: Domingo | D28: Segunda-feira | E28: Terça-feira | F28: Quarta-feira | G28: Quinta-feira | H28: Sexta-feira
B29: 44751 | C29: 44752 | D29: 44753 | E29: 44754 | F29: 44755 | G29: 44756 | H29: 44757
A30: Penha | B30: ANDRESSA | C30: ANDRESSA | D30: Andressa | E30: Andressa | F30: Andressa | G30: Andressa | H30: Andressa
B31: Isadora | C31: ISADORA | D31: ISADORA | E31: Isadora | F31: Isadora | G31: Isadora | H31: Isadora
B32: ANDRÉIA | C32: Andréia | D32: Andréia | E32: ANDRÉIA | F32: Andréia | G32: Andréia | H32: Andréia
B33: ANDRIELE | C33: ANDRIELE | D33: Andriele | E33: Andriele | F33: Andriele | G33: Andriele | H33: Andriele
A34: Piçarras | B34: KARLA | C34: Karla | D34: Karla | E34: KARLA | F34: Karla | G34: Karla | H34: Karla
B35: Laura | C35: LAURA | D35: LAURA | E35: Laura | F35: Laura | G35: Laura | H35: Laura
B36: Iara | C36: Iara | D36: Iara | E36: IARA | F36: Iara | G36: Iara | H36: Iara
B37: Roberto | C37: ROBERTO | D37: ROBERTO | E37: Roberto | F37: Roberto | G37: Roberto | H37: Roberto
A38: Piçarras/Penha | B38: LUIZ | C38: LUIZ | D38: Luiz | E38: Luiz | F38: Luiz | G38: Luiz | H38: Luiz
B39: Diogo | C39: Diogo | D39: DIOGO | E39: Diogo | F39: Diogo | G39: Diogo | H39: Diogo
A40: Externo | B40: Miguel | C40: Miguel | D40: Miguel | E40: MIGUEL | F40: Miguel | G40: Miguel | H40: Miguel
...

Sheet Agosto_22
A1: ESCALA DE TRABALHO - AGOSTO_2022
